Workbook

Sheet Cases
A1: ="1"+1 -> 2
A2: ="1"&1 -> 11
A3: ="1/2/2025"+0 -> 45659
A4: ="$1,200"+0 -> 1200
A5: ="12%"+0 -> 0.12
A6: ="1e3"+0 -> 1000
A7: =" 3 "+0 -> 3
A8: ="(5)"*1 -> -5
A9: ="3:30"*1 -> 0.14583333
A10: =""+0 -> #VALUE!
A11: ="abc"+1 -> #VALUE!
A12: ="TRUE"+0 -> #VALUE!
A13: =TRUE+TRUE -> 2
A14: =--"3" -> 3
A15: =-"-3" -> 3
A16: =Data!H1+1 -> 1
A17: =Data!H2+1 -> #VALUE!
A18: =Data!H3+1 -> #VALUE!
A19: =Data!H1&""
A20: =-Data!H1 -> 0
A21: =Data!C6*2 -> 10
A22: =Data!I4+0 -> #VALUE!
A23: =Data!I1+0 -> 1
A24: =SUM(Data!C6) -> 0
A25: =SUM(Data!C6+0) -> 5
A26: =COUNT("5",5,TRUE,"x") -> 3
A27: =MAX(Data!I1:I4) -> 0
A28: =MAX(TRUE,0) -> 1
A29: =1<"1" -> TRUE
A30: ="a"<"B" -> TRUE
A31: ="a"="A" -> TRUE
A32: ="Z"<FALSE -> TRUE
A33: =FALSE<TRUE -> TRUE
A34: =TRUE>1 -> TRUE
A35: =FALSE=0 -> FALSE
A36: ="10"<"9" -> TRUE
A37: ="abc"<"abcd" -> TRUE
A38: ="b"<"aa" -> FALSE
A39: ="é">"e" -> TRUE
A40: ="a"<"b " -> TRUE
...

Sheet Data
A1: 3 | B1: 2 | C1: 10 | G1: #N/A | I1: TRUE | AC1: 1 | AD1: 2 | AE1: 3
A2: 1 | B2: 7 | C2: text | G2: #DIV/0! | H2: ="" | I2: FALSE | AC2: 4 | AD2: 5 | AE2: 6
A3: 4 | B3: 1 | C3: TRUE | G3: 7 | I3: TRUE | AC3: 7 | AD3: 8 | AE3: 9
A4: 1 | B4: 8 | H4: 0 | I4: TRUE | AC4: 10 | AD4: 11 | AE4: 12
A5: 5 | B5: 2 | C5: 20
A6: 9 | B6: 8 | C6: 5
A7: 2 | B7: 1 | C7: FALSE
A8: 6 | B8: 8 | C8: 30
A9: 5 | B9: 2
A10: 3 | B10: 8
