Workbook

Sheet Cases
A1: =COUNTIF(Data!E1:E6,"apple") -> 2
A2: =COUNTIF(Data!E1:E6,"a*") -> 3
A3: =COUNTIF(Data!E1:E6,"?pple") -> 2
A4: =COUNTIF(Data!E1:E6,"*e") -> 4
A5: =COUNTIF(Data!E1:E6,"*p*e*") -> 3
A6: =COUNTIF(Data!E1:E6,"????") -> 1
A7: =COUNTIF(Data!E1:E6,"<>apple") -> 4
A8: =COUNTIF(Data!E1:E6,"<c") -> 4
A9: =COUNTIF(Data!A1:A10,">=3") -> 7
A10: =COUNTIF(Data!A1:A10,3) -> 2
A11: =COUNTIF(Data!A1:A10,"3") -> 2
A12: =COUNTIF(Data!A1:A10,"=3") -> 2
A13: =COUNTIF(Data!A1:A10,"<>3") -> 8
A14: =COUNTIF(Data!A1:A10,">"&Data!A1) -> 5
A15: =COUNTIF(Data!A1:A10,"<"&AVERAGE(Data!A1:A10)) -> 5
A16: =COUNTIF(Data!C1:C8,"<>") -> 7
A17: =COUNTIF(Data!C1:C8,"") -> 1
A18: =COUNTIF(Data!C1:C8,"=") -> 1
A19: =COUNTIF(Data!H1:H4,"") -> 2
A20: =COUNTIF(Data!H1:H4,"=") -> 1
A21: =COUNTIF(Data!C1:C8,TRUE) -> 1
A22: =COUNTIF(Data!C1:C8,"TRUE") -> 1
A23: =COUNTIF(Data!C1:C8,"5") -> 1
A24: =COUNTIF(Data!C1:C8,">5") -> 3
A25: =COUNTIF(Data!C1:C8,"*") -> 2
A26: =COUNTIF(Data!V1:V8,"a") -> 3
A27: =COUNTIF(Data!AG1:AG4,"a~*b") -> 1
A28: =COUNTIF(Data!AG1:AG4,"a?b") -> 3
A29: =COUNTIF(Data!AG1:AG4,"a~?b") -> 1
A30: =COUNTIF(Data!AG1:AG4,"a~~b") -> 0
A31: =COUNTIF(Data!F1:F6,">"&DATE(2024,6,1)) -> 2
A32: =COUNTIF(Data!F1:F6,">1/1/2025") -> 1
A33: =COUNTIF(Data!G1:G3,"#N/A") -> 1
A34: =COUNTIF(Data!X1:X8,">=2.2") -> 7
A35: =SUMIF(Data!A1:A10,">3") -> 29
A36: =SUMIF(Data!K2:K6,">102",Data!M2:M6) -> 227
A37: =SUMIF(Data!L2:L6,"?o?",Data!M2:M6) -> 95
A38: =SUMIF(Data!E1:E6,"apple*",Data!A1:A6) -> 13
A39: =SUMIF(Data!A1:A10,"x") -> 0
A40: =AVERAGEIF(Data!M2:M6,">80") -> 92.666667
...

Sheet Data
A1: 3 | B1: 2 | C1: 10 | E1: apple | F1: 45306 | G1: #N/A | K1: id | L1: name | M1: score | V1: 3 | X1: 1.1 | AA1: score | AB1: name | AG1: a*b
A2: 1 | B2: 7 | C2: text | E2: Banana | F2: 45351 | G2: #DIV/0! | H2: ="" | K2: 101 | L2: Ann | M2: 88 | V2: a | X2: 2.9 | AA2: >80 | AB2: B* | AG2: a?b
A3: 4 | B3: 1 | C3: TRUE | E3: cherry | F3: 45657 | G3: 7 | K3: 102 | L3: Bob | M3: 95 | V3: 3 | X3: 2.2 | AG3: ab
A4: 1 | B4: 8 | E4: apple pie | F4: 45717 | H4: 0 | K4: 103 | L4: Cy | M4: 72 | V4: b | X4: 4.8 | AG4: a~b
A5: 5 | B5: 2 | C5: 20 | E5: date | F5: 59 | K5: 104 | L5: Dee | M5: 95 | V5: a | X5: 3.9
A6: 9 | B6: 8 | C6: 5 | E6: Apple | F6: 61 | K6: 105 | L6: Eve | M6: 60 | V6: 5 | X6: 6.2
A7: 2 | B7: 1 | C7: FALSE | V7: A | X7: 5.1
A8: 6 | B8: 8 | C8: 30 | X8: 7.9
A9: 5 | B9: 2
A10: 3 | B10: 8
