Workbook

Sheet Cases
A1: =DATE(2025,1,1) -> 45658
A2: =DATE(2025,13,1) -> 46023
A3: =DATE(2025,1,0) -> 45657
A4: =DATE(2025,0,1) -> 45627
A5: =DATE(2025,-1,15) -> 45611
A6: =DATE(2025,1,-1) -> 45656
A7: =DATE(2025,2,29) -> 45717
A8: =DATE(2024,2,29) -> 45351
A9: =DATE(99,1,1) -> 36161
A10: =DATE(1899,12,31) -> 693962
A11: =DATE(1900,1,1) -> 1
A12: =DATE(1900,2,28) -> 59
A13: =DATE(1900,2,29) -> 60
A14: =DATE(1900,3,1) -> 61
A15: =DATE(1900,1,0) -> 0
A16: =DATE(-1,1,1) -> #NUM!
A17: =DATE(10000,1,1) -> #NUM!
A18: =DATE(9999,12,31) -> 2958465
A19: =DATE(2025.9,1.9,1.9) -> 45658
A20: =DATE(1900,3,1)-DATE(1900,2,28) -> 2
A21: =TIME(12,30,0) -> 0.52083333
A22: =TIME(25,0,0) -> 0.041666667
A23: =TIME(0,90,0) -> 0.0625
A24: =TIME(23,59,59) -> 0.99998843
A25: =TIME(0,0,-1) -> #NUM!
A26: =YEAR(45306) -> 2024
A27: =MONTH(45351) -> 2
A28: =DAY(45351) -> 29
A29: =YEAR(0) -> 1900
A30: =MONTH(0) -> 1
A31: =DAY(0) -> 0
A32: =DAY(60) -> 29
A33: =MONTH(60) -> 2
A34: =DAY(61) -> 1
A35: =YEAR(2958465) -> 9999
A36: =YEAR(2958466) -> #NUM!
A37: =YEAR(-1) -> #NUM!
A38: =YEAR("2025-03-01") -> 2025
A39: =MONTH("Mar 1, 2025") -> 3
A40: =DAY("2025/3/14") -> 14
...

Sheet Data
F1: 45306 | T1: 45658
F2: 45351 | T2: 45677
F3: 45657 | T3: 45705
F4: 45717
F5: 59
F6: 61
