Workbook

Sheet Cases
A1: =PMT(0.05/12,360,200000) -> -1073.6432
A2: =PMT(0,12,1200) -> -100
A3: =PMT(0.05/12,360,200000,0,1) -> -1069.1883
A4: =PMT(0.08,10,0,10000) -> -690.29489
A5: =PMT(0.05,0,100) -> #NUM!
A6: =PPMT(0.1/12,1,36,8000) -> -191.47083
A7: =PPMT(0.1,2,10,100000) -> -6901.9934
A8: =PPMT(0.1,11,10,100000) -> #NUM!
A9: =IPMT(0.1/12,1,36,8000) -> -66.666667
A10: =IPMT(0.1,3,3,8000) -> -292.44713
A11: =IPMT(0.05,1,10,1000,0,1) -> 0
A12: =PV(0.08/12,240,500) -> -59777.146
A13: =PV(0,10,100) -> -1000
A14: =PV(0.05,10,-100,0,1) -> 810.78217
A15: =FV(0.06/12,10,-200,-500,1) -> 2581.4034
A16: =FV(0,10,-100) -> 1000
A17: =FV(0.05,10,-100) -> 1257.7893
A18: =FV(0.1,2,0,-100) -> 121
A19: =NPER(0.12/12,-100,-1000,10000,1) -> 59.673866
A20: =NPER(0,-100,1000) -> 10
A21: =NPER(0.05,100,1000) -> -8.3103862
A22: =RATE(48,-200,8000) -> 0.0077014725
A23: =RATE(10,-100,1000,0,0,0.1) -> -1.9633517e-10
A24: =RATE(12,-100,-1000) -> #NUM!
A25: =RATE(360,-1073.64,200000)*12 -> 0.049999734
A26: =NPV(0.1,Data!R2:R6)+Data!R1 -> 177.65801
A27: =NPV(0.1,-10000,3000,4200,6800) -> 1188.4434
A28: =NPV(0.1,Data!C1:C8) -> 48.159279
A29: =IRR(Data!R1:R6) -> 0.17638915
A30: =IRR(Data!R1:R6,0.1) -> 0.17638915
A31: =IRR({-100,-10}) -> #NUM!
A32: =IRR({-70000,12000,15000,18000,21000,26000}) -> 0.086630948
A33: =XNPV(0.09,Data!R1:R6,Data!S1:S6) -> 418.71273
A34: =XNPV(0.09,Data!R1:R6,Data!S1:S5) -> #NUM!
A35: =XIRR(Data!R1:R6,Data!S1:S6) -> 0.91537405
A36: =XIRR(Data!R1:R6,Data!S1:S6,0.2) -> 0.91537405
A37: =MIRR(Data!R1:R6,0.1,0.12) -> 0.14699635
A38: =MIRR({100,200},0.1,0.1) -> #DIV/0!
A39: =SLN(30000,7500,10) -> 2250
A40: =SYD(30000,7500,10,1) -> 4090.9091
...

Sheet Data
C1: 10 | R1: -1000 | S1: 45292
C2: text | R2: 300 | S2: 45383
C3: TRUE | R3: 400 | S3: 45474
R4: 500 | S4: 45566
C5: 20 | R5: 200 | S5: 45658
C6: 5 | R6: 100 | S6: 45748
C7: FALSE
C8: 30
