Workbook

Sheet Cases
A1: =ISBLANK(Data!H1) -> TRUE
A2: =ISBLANK(Data!H2) -> FALSE
A3: =ISBLANK(Data!H3) -> FALSE
A4: =ISBLANK("") -> FALSE
A5: =ISNUMBER(Data!A1) -> TRUE
A6: =ISNUMBER(Data!C6) -> FALSE
A7: =ISNUMBER("5") -> FALSE
A8: =ISNUMBER(Data!F1) -> TRUE
A9: =ISNUMBER(1/0) -> FALSE
A10: =ISTEXT(Data!C6) -> TRUE
A11: =ISTEXT(Data!H2) -> TRUE
A12: =ISTEXT(Data!H1) -> FALSE
A13: =ISNONTEXT(Data!H1) -> TRUE
A14: =ISLOGICAL(Data!I1) -> TRUE
A15: =ISLOGICAL(Data!I4) -> FALSE
A16: =ISERROR(Data!G1) -> TRUE
A17: =ISERROR(Data!G3) -> FALSE
A18: =ISERR(Data!G1) -> FALSE
A19: =ISERR(Data!G2) -> TRUE
A20: =ISNA(Data!G1) -> TRUE
A21: =ISNA(Data!G2) -> FALSE
A22: =ISREF(Data!A1) -> TRUE
A23: =ISREF("Data!A1") -> FALSE
A24: =_xlfn.ISFORMULA(Data!AF1) -> TRUE
A25: =_xlfn.ISFORMULA(Data!AF2) -> FALSE
A26: =ISEVEN(4) -> TRUE
A27: =ISEVEN(2.9) -> TRUE
A28: =ISEVEN(Data!H1) -> TRUE
A29: =ISODD(3) -> TRUE
A30: =ISODD(-3.5) -> TRUE
A31: =ISODD("x") -> #VALUE!
A32: =N(5) -> 5
A33: =N("5") -> 0
A34: =N(TRUE) -> 1
A35: =N(Data!E1) -> 0
A36: =N(Data!G1) -> #N/A
A37: =N(Data!F1) -> 45306
A38: =TYPE(1) -> 1
A39: =TYPE("a") -> 2
A40: =TYPE(TRUE) -> 4
...

Sheet Data
A1: 3 | C1: 10 | E1: apple | F1: 45306 | G1: #N/A | I1: TRUE | AF1: =1+1 -> 2
A2: 1 | C2: text | E2: Banana | F2: 45351 | G2: #DIV/0! | H2: ="" | I2: FALSE | AF2: plain
A3: 4 | C3: TRUE | E3: cherry | F3: 45657 | G3: 7 | I3: TRUE
A4: 1 | E4: apple pie | F4: 45717 | H4: 0 | I4: TRUE
A5: 5 | C5: 20 | E5: date | F5: 59
A6: 9 | C6: 5 | E6: Apple | F6: 61
A7: 2 | C7: FALSE
A8: 6 | C8: 30
A9: 5
A10: 3
