Workbook

Sheet Cases
A1: =IF(TRUE,1,2) -> 1
A2: =IF(0,"yes","no") -> no
A3: =IF("TRUE",1,2) -> 1
A4: =IF("x",1,2) -> #VALUE!
A5: =IF(Data!H1,1,2) -> 2
A6: =IF(1>2,1) -> FALSE
A7: =IF(1<2,,"no") -> 0
A8: =IF(Data!G1,1,2) -> #N/A
A9: =IF(Data!A1>3,"big","small") -> small
A10: =IF(TRUE,1,1/0) -> 1
A11: {=_xlfn.IFS(1>2,"a",2>1,"b")} -> b
A12: {=_xlfn.IFS(FALSE,1)} -> #N/A
A13: {=_xlfn.IFS(Data!A1=3,"three",TRUE,"other")} -> three
A14: =AND(TRUE,TRUE) -> TRUE
A15: =AND(TRUE,FALSE) -> FALSE
A16: =AND(1,2) -> TRUE
A17: =AND(0,1) -> FALSE
A18: =AND(Data!C1:C8) -> FALSE
A19: =AND(Data!E1:E3) -> #VALUE!
A20: =AND(Data!H1) -> #VALUE!
A21: =AND("TRUE",TRUE) -> TRUE
A22: =AND({TRUE,FALSE}) -> FALSE
A23: =AND(Data!I1:I4) -> FALSE
A24: =AND(Data!G1,FALSE) -> #N/A
A25: =OR(FALSE,FALSE) -> FALSE
A26: =OR(FALSE,1) -> TRUE
A27: =OR(Data!I1:I4) -> TRUE
A28: =OR(Data!E1:E3) -> #VALUE!
A29: =OR(Data!G1,TRUE) -> #N/A
A30: =_xlfn.XOR(TRUE,TRUE) -> FALSE
A31: =_xlfn.XOR(TRUE,FALSE,TRUE) -> FALSE
A32: =_xlfn.XOR(Data!I1:I4) -> FALSE
A33: =NOT(TRUE) -> FALSE
A34: =NOT(0) -> TRUE
A35: =NOT(Data!H1) -> TRUE
A36: =NOT("x") -> #VALUE!
A37: =NOT(2) -> FALSE
A38: =TRUE() -> TRUE
A39: =FALSE() -> FALSE
A40: =IFERROR(1/0,"div") -> div
...

Sheet Data
A1: 3 | C1: 10 | E1: apple | G1: #N/A | I1: TRUE
A2: 1 | C2: text | E2: Banana | G2: #DIV/0! | H2: ="" | I2: FALSE
A3: 4 | C3: TRUE | E3: cherry | G3: 7 | I3: TRUE
A4: 1 | E4: apple pie | H4: 0 | I4: TRUE
A5: 5 | C5: 20 | E5: date
A6: 9 | C6: 5 | E6: Apple
A7: 2 | C7: FALSE
A8: 6 | C8: 30
A9: 5
A10: 3
