Workbook

Sheet Cases
A1: =VLOOKUP(102,Data!K2:M6,2,FALSE) -> Bob
A2: =VLOOKUP(106,Data!K2:M6,2,FALSE) -> #N/A
A3: =VLOOKUP(103.5,Data!K2:M6,3,TRUE) -> 72
A4: =VLOOKUP(100,Data!K2:M6,2,TRUE) -> #N/A
A5: =VLOOKUP(102,Data!K2:M6,2) -> Bob
A6: =VLOOKUP("bob",Data!L2:M6,2,FALSE) -> 95
A7: =VLOOKUP("B*",Data!L2:M6,2,FALSE) -> 95
A8: =VLOOKUP(102,Data!K2:M6,4,FALSE) -> #REF!
A9: =VLOOKUP(102,Data!K2:M6,0,FALSE) -> #VALUE!
A10: =VLOOKUP("102",Data!K2:M6,2,FALSE) -> #N/A
A11: =VLOOKUP(95,Data!M2:M6,1,FALSE) -> 95
A12: =HLOOKUP(3,Data!K10:P11,2,FALSE) -> three
A13: =HLOOKUP(3.5,Data!K10:P11,2,TRUE) -> three
A14: =HLOOKUP(7,Data!K10:P11,2,FALSE) -> #N/A
A15: =HLOOKUP(3,Data!K10:P11,3,FALSE) -> #REF!
A16: =LOOKUP(35,Data!N1:N6,Data!O1:O6) -> C
A17: =LOOKUP(5,Data!N1:N6,Data!O1:O6) -> #N/A
A18: =LOOKUP(100,Data!N1:N6,Data!O1:O6) -> F
A19: =LOOKUP("C",Data!O1:O6,Data!N1:N6) -> 30
A20: =LOOKUP(3,{1,2,3;"a","b","c"}) -> c
A21: =MATCH(30,Data!N1:N6,0) -> 3
A22: =MATCH(35,Data!N1:N6,1) -> 3
A23: =MATCH(35,Data!N1:N6) -> 3
A24: =MATCH(35,Data!P1:P6,-1) -> 3
A25: =MATCH(5,Data!N1:N6,1) -> #N/A
A26: =MATCH(70,Data!N1:N6,0) -> #N/A
A27: =MATCH("c",Data!O1:O6,0) -> 3
A28: =MATCH("b*",Data!E1:E6,0) -> 2
A29: =MATCH("?pple",Data!E1:E6,0) -> 1
A30: =MATCH(TRUE,Data!I1:I4,0) -> 1
A31: =MATCH(95,Data!M2:M6,0) -> 2
A32: =INDEX(Data!K1:M6,3,2) -> Bob
A33: =INDEX(Data!K1:M6,7,1) -> #REF!
A34: =INDEX(Data!N1:N6,4) -> 40
A35: =INDEX(Data!K10:P10,3) -> 3
A36: =SUM(INDEX(Data!K2:M6,0,3)) -> 410
A37: =INDEX((Data!A1:A3,Data!B1:B3),2,1,2) -> 7
A38: =INDEX({1,2;3,4},2,2) -> 4
A39: =INDEX(Data!L2:L6,MATCH(95,Data!M2:M6,0)) -> Bob
A40: =INDEX(Data!M2:M6,MATCH("dee",Data!L2:L6,0)) -> 95
...

Sheet Data
A1: 3 | B1: 2 | C1: 10 | D1: -2.5 | E1: apple | I1: TRUE | K1: id | L1: name | M1: score | N1: 10 | O1: A | P1: 60 | V1: 3
A2: 1 | B2: 7 | C2: text | D2: 0 | E2: Banana | I2: FALSE | K2: 101 | L2: Ann | M2: 88 | N2: 20 | O2: B | P2: 50 | V2: a
A3: 4 | B3: 1 | C3: TRUE | D3: 1.25 | E3: cherry | I3: TRUE | K3: 102 | L3: Bob | M3: 95 | N3: 30 | O3: C | P3: 40 | V3: 3
A4: 1 | B4: 8 | D4: -7 | E4: apple pie | I4: TRUE | K4: 103 | L4: Cy | M4: 72 | N4: 40 | O4: D | P4: 30 | V4: b
A5: 5 | B5: 2 | C5: 20 | D5: 100 | E5: date | K5: 104 | L5: Dee | M5: 95 | N5: 50 | O5: E | P5: 20 | V5: a
A6: 9 | B6: 8 | C6: 5 | D6: 0.001 | E6: Apple | K6: 105 | L6: Eve | M6: 60 | N6: 60 | O6: F | P6: 10 | V6: 5
A7: 2 | B7: 1 | C7: FALSE | V7: A
A8: 6 | B8: 8 | C8: 30
A9: 5 | B9: 2
A10: 3 | B10: 8 | K10: 1 | L10: 2 | M10: 3 | N10: 4 | O10: 5 | P10: 6
K11: one | L11: two | M11: three | N11: four | O11: five | P11: six
