Workbook

Sheet Cases
A1: =SUM(Data!A1:A10) -> 39
A2: =SUM(Data!A1:A10,Data!B1:B10) -> 86
A3: =SUM(Data!C1:C8) -> 60
A4: =SUM(1,"2",TRUE) -> 4
A5: =SUM("x") -> #VALUE!
A6: =SUM(Data!G1:G3) -> #N/A
A7: =SUM(Data!D1:D6) -> 91.751
A8: =SUMSQ(Data!A1:A5) -> 52
A9: =SUMSQ(Data!C1:C8) -> 1400
A10: =SUMPRODUCT(Data!A1:A10,Data!B1:B10) -> 191
A11: {=SUMPRODUCT((Data!A1:A10>3)*Data!B1:B10)} -> 21
A12: =SUMPRODUCT(Data!A1:A3,Data!B1:B4) -> #VALUE!
A13: =SUMPRODUCT(Data!C1:C8) -> 60
A14: {=SUMPRODUCT(--(Data!E1:E6="apple"))} -> 2
A15: =PRODUCT(Data!A1:A5) -> 60
A16: =PRODUCT(Data!C1:C8) -> 6000
A17: =PRODUCT(2,"3") -> 6
A18: =PRODUCT(Data!H1) -> 0
A19: =ABS(-3.5) -> 3.5
A20: =ABS(Data!D1) -> 2.5
A21: =SIGN(-0.001) -> -1
A22: =SIGN(0) -> 0
A23: =ROUND(2.5,0) -> 3
A24: =ROUND(-2.5,0) -> -3
A25: =ROUND(1.005,2) -> 1.01
A26: =ROUND(2.675,2) -> 2.68
A27: =ROUND(0.285,2) -> 0.29
A28: =ROUND(5.55,1) -> 5.6
A29: =ROUND(1234.5678,-2) -> 1200
A30: =ROUND(-0.5,0) -> -1
A31: =ROUND(0.1+0.2,15) -> 0.3
A32: =ROUND(1E+300,-299) -> 1e+300
A33: =ROUND(123.456,1.9) -> 123.5
A34: =ROUNDUP(3.14159,2) -> 3.15
A35: =ROUNDUP(-3.14159,2) -> -3.15
A36: =ROUNDUP(31415.9,-2) -> 31500
A37: =ROUNDUP(0.1*3,1) -> 0.3
A38: =ROUNDDOWN(3.99,0) -> 3
A39: =ROUNDDOWN(-3.99,0) -> -3
A40: =ROUNDDOWN(0.3*3,1) -> 0.9
...

Sheet Data
A1: 3 | B1: 2 | C1: 10 | D1: -2.5 | E1: apple | G1: #N/A
A2: 1 | B2: 7 | C2: text | D2: 0 | E2: Banana | G2: #DIV/0! | H2: =""
A3: 4 | B3: 1 | C3: TRUE | D3: 1.25 | E3: cherry | G3: 7
A4: 1 | B4: 8 | D4: -7 | E4: apple pie | H4: 0
A5: 5 | B5: 2 | C5: 20 | D5: 100 | E5: date
A6: 9 | B6: 8 | C6: 5 | D6: 0.001 | E6: Apple
A7: 2 | B7: 1 | C7: FALSE
A8: 6 | B8: 8 | C8: 30
A9: 5 | B9: 2
A10: 3 | B10: 8
