Workbook

Sheet Cases
A1: =SUM(Jan:Mar!B2) -> 111 | C1: =Data!A1*2 -> 6 | D1: =Data!$AC$1+Data!AC$1*10+Data!$AC2*100+Data!AC2*1000 -> 4411 | E1: =Data!$AC$1+Data!AD$1*10+Data!$AC2*100+Data!AD2*1000 -> 5421 | F1: =Data!$AC$1+Data!AE$1*10+Data!$AC2*100+Data!AE2*1000 -> 6431 | G1: =SUM(Data!$AC$1:AC1) -> 1 | H1: {=Data!AC1:AC3*10} -> 10
A2: =SUM(Jan:Mar!B2:C3) -> 710 | C2: =Data!A2*2 -> 2 | D2: =Data!$AC$1+Data!AC$1*10+Data!$AC3*100+Data!AC3*1000 -> 7711 | E2: =Data!$AC$1+Data!AD$1*10+Data!$AC3*100+Data!AD3*1000 -> 8721 | F2: =Data!$AC$1+Data!AE$1*10+Data!$AC3*100+Data!AE3*1000 -> 9731 | G2: =SUM(Data!$AC$1:AC2) -> 5 | H2: 40
A3: =AVERAGE(Jan:Mar!B2) -> 37 | C3: =Data!A3*2 -> 8 | D3: =Data!$AC$1+Data!AC$1*10+Data!$AC4*100+Data!AC4*1000 -> 11011 | E3: =Data!$AC$1+Data!AD$1*10+Data!$AC4*100+Data!AD4*1000 -> 12021 | F3: =Data!$AC$1+Data!AE$1*10+Data!$AC4*100+Data!AE4*1000 -> 13031 | G3: =SUM(Data!$AC$1:AC3) -> 12 | H3: 70
A4: =COUNT(Jan:Mar!B2:C3) -> 11 | C4: =Data!A4*2 -> 2 | G4: =SUM(Data!$AC$1:AC4) -> 22
A5: =COUNTA(Jan:Mar!B2:C3) -> 12 | C5: =Data!A5*2 -> 10 | H5: {=SUM(Data!A1:A10*Data!B1:B10)} -> 191
A6: =MAX(Jan:Mar!C3) -> 40 | H6: {=MAX(IF(Data!A1:A10<5,Data!A1:A10))} -> 4
A7: =MIN(Jan:Mar!B2:C3) -> 1 | H7: {=SUM(IF(Data!A1:A10>3,1,0))} -> 5
A8: =PRODUCT(Jan:Feb!B2) -> 10
A9: =SUM(Feb!B2:B3) -> 40
A10: =STDEV(Jan:Mar!B2) -> 54.744863
A11: =SUM(Jan!B2:C3,Mar!B2) -> 110
A12: =SUM('Jan:Sheet 2'!A1) -> 5
A13: ='Sheet 2'!A1*2 -> 10
A14: ='Sheet 2'!A2&"!" -> five!
A15: =SUM({1,2,3}) -> 6
A16: =SUM({1,2;3,4}) -> 10
A17: {=SUM({1,2;3,4}*{1;2})} -> 17
A18: =INDEX({1,2;3,4},2,1) -> 3
A19: {=INDEX({"a","b","c"},3)} -> c
A20: =MAX({-1,-5,-3}) -> -1
A21: =SUM({1,#N/A}) -> #N/A
A22: =AND({TRUE,FALSE}) -> FALSE
A23: =_xlfn.CONCAT({"a","b";"c","d"}) -> abcd
A24: =MATCH(3,{1,3,5},0) -> 2
A25: =VLOOKUP(2,{1,"a";2,"b"},2,FALSE) -> b
A26: =SUMPRODUCT({1,2},{3,4}) -> 11
A27: =COUNTA({1,"",TRUE}) -> 3
A28: =AVERAGE({1,"2",TRUE}) -> 1
A29: =SUM({"1",2}) -> 2
A30: =SUM({1.5,-0.5}) -> 1
A31: {=SUM({1,2,3}*2)} -> 12
A32: {=INDEX({1;2;3}+{10,20},3,2)} -> 23
A33: {=SUM({1,2}+{1,2,3})} -> #N/A
A34: =SUM(Data!Z:Z) -> 6
A35: =COUNT(Data!Z:Z) -> 3
A36: =ROWS(Data!Z:Z) -> 1048576
A37: =SUM(Data!20:20) -> 15
A38: =COLUMNS(Data!20:20) -> 16384
A39: {=Data!AC2:AE2 Data!AD1:AD4} -> 5
A40: =SUM((Data!AC1:AC2,Data!AE3:AE4)) -> 26
...

Sheet Data
A1: 3 | B1: 2 | Z1: 1 | AC1: 1 | AD1: 2 | AE1: 3
A2: 1 | B2: 7 | Z2: 2 | AC2: 4 | AD2: 5 | AE2: 6
A3: 4 | B3: 1 | Z3: 3 | AC3: 7 | AD3: 8 | AE3: 9
A4: 1 | B4: 8 | AC4: 10 | AD4: 11 | AE4: 12
A5: 5 | B5: 2
A6: 9 | B6: 8
A7: 2 | B7: 1
A8: 6 | B8: 8
A9: 5 | B9: 2
A10: 3 | B10: 8
A20: 1 | B20: 2 | C20: 3 | D20: 4 | E20: 5

Sheet Jan
B2: 1 | C2: 2
B3: 3 | C3: 4

Sheet Feb
B2: 10 | C2: 20
B3: 30 | C3: 40

Sheet Mar
B2: 100 | C2: 200
B3: 300 | C3: x

Sheet Sheet 2
A1: 5
A2: five
