Workbook

Sheet Cases
A1: =AVERAGE(Data!A1:A10) -> 3.9
A2: =AVERAGE(Data!C1:C8) -> 20
A3: =AVERAGE(1,"2",TRUE) -> 1.3333333
A4: =AVERAGE(Data!H1) -> #DIV/0!
A5: =AVERAGEA(Data!C1:C8) -> 8.7142857
A6: =MEDIAN(Data!A1:A10) -> 3.5
A7: =MEDIAN(Data!A1:A9) -> 4
A8: =MODE(Data!A1:A10) -> 3
A9: =_xlfn.MODE.SNGL(Data!A1:A10) -> 3
A10: {=INDEX(_xlfn.MODE.MULT(Data!A1:A10),2)} -> 1
A11: =MODE(1,2,3) -> #N/A
A12: =COUNT(Data!C1:C8) -> 3
A13: =COUNT(1,"2","x",TRUE) -> 3
A14: =COUNTA(Data!C1:C8) -> 7
A15: =COUNTA(Data!H1:H4) -> 3
A16: =COUNTBLANK(Data!H1:H4) -> 2
A17: =COUNTBLANK(Data!C1:C8) -> 1
A18: =MAX(Data!A1:A10) -> 9
A19: =MIN(Data!D1:D6) -> -7
A20: =MAX(Data!C1:C8) -> 30
A21: =MAXA(Data!C1:C8) -> 30
A22: =MINA(Data!C1:C8) -> 0
A23: =MAX(Data!E1:E6) -> 0
A24: =MAX("5",3) -> 5
A25: =MIN(Data!G1:G3) -> #N/A
A26: =LARGE(Data!A1:A10,2) -> 6
A27: =LARGE(Data!A1:A10,0) -> #NUM!
A28: =LARGE(Data!A1:A10,11) -> #NUM!
A29: =SMALL(Data!A1:A10,3) -> 2
A30: =SMALL(Data!D1:D6,1) -> -7
A31: =RANK(5,Data!A1:A10) -> 3
A32: =RANK(5,Data!A1:A10,1) -> 7
A33: =_xlfn.RANK.EQ(1,Data!A1:A10) -> 9
A34: =_xlfn.RANK.AVG(1,Data!A1:A10) -> 9.5
A35: =_xlfn.RANK.AVG(5,Data!A1:A10,1) -> 7.5
A36: =RANK(7,Data!A1:A10) -> #N/A
A37: =PERCENTILE(Data!A1:A10,0.25) -> 2.25
A38: =_xlfn.PERCENTILE.INC(Data!A1:A10,0.9) -> 6.3
A39: =_xlfn.PERCENTILE.EXC(Data!A1:A10,0.25) -> 1.75
A40: =_xlfn.PERCENTILE.EXC(Data!A1:A10,0.05) -> #NUM!
...

Sheet Data
A1: 3 | B1: 2 | C1: 10 | D1: -2.5 | E1: apple | G1: #N/A | W1: 2.5 | X1: 1.1 | Y1: 0
A2: 1 | B2: 7 | C2: text | D2: 0 | E2: Banana | G2: #DIV/0! | H2: ="" | W2: 3.7 | X2: 2.9 | Y2: 0
A3: 4 | B3: 1 | C3: TRUE | D3: 1.25 | E3: cherry | G3: 7 | W3: 1.2 | X3: 2.2 | Y3: 0
A4: 1 | B4: 8 | D4: -7 | E4: apple pie | H4: 0 | W4: 8.8 | X4: 4.8
A5: 5 | B5: 2 | C5: 20 | D5: 100 | E5: date | W5: 4.4 | X5: 3.9
A6: 9 | B6: 8 | C6: 5 | D6: 0.001 | E6: Apple | W6: 6.1 | X6: 6.2
A7: 2 | B7: 1 | C7: FALSE | W7: 5.5 | X7: 5.1
A8: 6 | B8: 8 | C8: 30 | W8: 7.3 | X8: 7.9
A9: 5 | B9: 2
A10: 3 | B10: 8
