Workbook

Sheet Cases
A1: =LEN("hello") -> 5
A2: =LEN("") -> 0
A3: =LEN(Data!H1) -> 0
A4: =LEN(Data!H3) -> 1
A5: =LEN(12.5) -> 4
A6: =LEN(1/3) -> 17
A7: =LEN(TRUE) -> 4
A8: =LEN("é") -> 1
A9: =LEN(_xlfn.UNICHAR(128512)) -> 1
A10: =LEN(Data!U3) -> 7
A11: =LEFT("hello",2) -> he
A12: =LEFT("hello") -> h
A13: =LEFT("hello",0)
A14: =LEFT("hello",10) -> hello
A15: =LEFT("hello",-1) -> #VALUE!
A16: =LEFT(1234,2) -> 12
A17: =RIGHT("hello",3) -> llo
A18: =RIGHT("hello",0)
A19: =MID("hello",2,3) -> ell
A20: =MID("hello",10,2)
A21: =MID("hello",0,2) -> #VALUE!
A22: =MID("hello",2,-1) -> #VALUE!
A23: =UPPER("MiXeD") -> MIXED
A24: =LOWER("MiXeD") -> mixed
A25: =PROPER("hello WORLD o'neil 2nd-place") -> Hello World O'Neil 2Nd-Place
A26: =PROPER("école élève") -> École Élève
A27: =UPPER(Data!U3) -> ÜNÏCÖDÉ
A28: =TRIM(Data!U1) -> lead and trail
A29: =TRIM(Data!U2) -> a b c
A30: =TRIM(" ")
A31: =CLEAN("a"&CHAR(7)&"b") -> ab
A32: =CLEAN(CHAR(10)&"x") -> x
A33: =CONCATENATE("a",1,TRUE) -> a1TRUE
A34: =_xlfn.CONCAT(Data!E1:E3) -> appleBananacherry
A35: =_xlfn.CONCAT("a",Data!A1:A3) -> a314
A36: =_xlfn.TEXTJOIN(", ",TRUE,Data!E1:E3) -> apple, Banana, cherry
A37: =_xlfn.TEXTJOIN("-",FALSE,Data!H1:H3) -> --
A38: =_xlfn.TEXTJOIN("-",TRUE,Data!H1:H3)
A39: =_xlfn.TEXTJOIN({",",";"},TRUE,"a","b","c") -> a,b;c
A40: ="a"&1.5&TRUE -> a1.5TRUE
...

Sheet Data
A1: 3 | E1: apple | U1: lead and trail
A2: 1 | E2: Banana | H2: ="" | U2: a b c
A3: 4 | E3: cherry | U3: Ünïcödé
A4: 1 | E4: apple pie | H4: 0 | U4: x-y-z-w
A5: 5 | E5: date
A6: 9 | E6: Apple
A7: 2
A8: 6
A9: 5
A10: 3
